Workbook

Sheet Guide
A1: 608 Smith Avenue Pro Forma — Guide
A2: Decision model for Oct 2026–May 2030. Base is the default scenario; all yellow cells on Inputs are editable.
A4: Purpose | B4: Use the model to assess Smith occupancy, founder compensation, the optional storefront, and the conditional second venue.
A6: How to use | B6: Action
A7: 1 | B7: Choose Downside, Base, or Upside in Inputs!B4. Dashboard and Annual Summary follow that selection.
A8: 2 | B8: Edit only yellow scenario cells. Formula cells carry cached values and recalculate when opened in Excel.
A9: 3 | B9: Review Smith occupancy and total labor after the six-month storefront ramp, then inspect cash and sensitivities.
A10: 4 | B10: Refresh available cash and resolve founder cash timing and pre-model founder deferred compensation before financing decisions.
A12: Editable input legend | B12: Yellow = editable input; blue/white = formula or explanatory output.
A13: Editable input | B13: Change these assumptions on Inputs; do not overwrite model formulas.
A15: Classification | B15: Meaning
A16: Observed | B16: Historical or snapshot value reported from source records.
A17: Owner-defined | B17: Fact or direction provided by the owner on or before 2026-09-24.
A18: Modeled | B18: Editable planning assumption, conversion, rate, or scenario choice.
A19: Unresolved | B19: Required fact not yet established; the shown value is an explicit modeled default.
A22: Core mechanics
A23: Smith storefront sales solve to the occupancy target after meal prep and frozen pizza, then ramp 35% / 50% / 65% / 80% / 90% / 100% over six months.
A24: Airbnb is nonfood revenue. Events include $1,350 food revenue per event. Personal-chef, Smith meal prep, storefront, and frozen pizza are food revenue.
A25: Food COGS applies only to food revenue; Airbnb variable cost applies only to Airbnb; payment fees are 3% of non-Airbnb revenue.
A26: Founder economic compensation is $7,500/month in total labor. Current cash salary timing, opening deferred balance, and backpay are separate editable inputs.
A27: Founder cash timing and any pre-model deferred balance/back-pay remain unresolved. Oct 2026 cash start and zero backpay are modeled defaults—not owner facts; opening cash is observed.
A28: Happy Monday sandwiches are excluded. Frozen pizza only is modeled, and all pizza is produced at Hopkins. Smith houses meal prep.
A30: Important disclosure
A31: This is a planning financial model, not tax, legal, or accounting advice. It excludes debt service and financing, income and sales taxes, inventory working capital, security deposits, and capital raises. Opening cash is a one-account snapshot, not complete liquidity. Validate assumptions with qualified advisers.

Sheet Inputs
A1: Inputs — Scenario Assumptions
A2: Select a scenario, then edit yellow cells. Classifications distinguish sourced facts from modeled or unresolved values.
A4: Selected Scenario | B4: Base | C4: Base is the default. Dashboard and Annual Summary formulas follow Inputs!B4.
A5: Classification vocabulary: Observed | Owner-defined | Modeled | Unresolved. Yellow cells are editable inputs.
A7: Assumption | B7: Classification | C7: Unit | D7: Downside | E7: Base | F7: Upside | G7: Rationale / provenance
A8: Smith Utilities | B8: Modeled | C8: $/month | D8: 1400 | E8: 1000 | F8: 700 | G8: Transfers to Local Effort in Mar 2027.
A9: Second Venue Activation | B9: Modeled | C9: 0/1 | D9: 0 | E9: 1 | F9: 1 | G9: 1 activates Jan 2027 revenue and $5,000 monthly rent; 0 declines the post-trial venue.
A10: Second Venue Trial Scale | B10: Modeled | C10: % of run-rate | D10: 0.5 | E10: 0.75 | F10: 1 | G10: Scales Oct–Dec 2026 trial revenue; no trial rent was supplied.
A11: Airbnb Weekends / Month | B11: Modeled | C11: weekends | D11: 1.5 | E11: 3 | F11: 4 | G11: Booked weekends at $2,400 each; Airbnb is nonfood revenue.
A12: Airbnb Variable Cost | B12: Modeled | C12: % Airbnb | D12: 0.25 | E12: 0.18 | F12: 0.12 | G12: Variable cost applies only to Airbnb revenue.
A13: Small Events / Month | B13: Modeled | C13: events | D13: 1 | E13: 2 | F13: 3 | G13: Second-venue event count at activated run-rate.
A14: Small Event Revenue / Event | B14: Owner-defined | C14: $/event | D14: 2100 | E14: 2100 | F14: 2100 | G14: $2,100 gross event revenue; $1,350 is food revenue.
A15: Event Food Revenue / Event | B15: Owner-defined | C15: $/event | D15: 1350 | E15: 1350 | F15: 1350 | G15: Food component used for food COGS; remainder is nonfood venue revenue.
A16: Personal Chef Packages / Month | B16: Modeled | C16: packages | D16: 1 | E16: 2 | F16: 4 | G16: Activated second-venue run-rate.
A17: Personal Chef Price | B17: Modeled | C17: $/package | D17: 800 | E17: 1200 | F17: 1800 | G17: Modeled package price; personal-chef revenue is food revenue.
A18: Meal Prep Starting Monthly Revenue | B18: Modeled | C18: $/month | D18: 4334.42 | E18: 4334.42 | F18: 4334.42 | G18: $4,334.42 monthly starting point derived from the owner-provided 4001 dollars per 28-day anchor.
A19: Meal Prep Monthly Growth | B19: Modeled | C19: %/month | D19: 0 | E19: 0.01 | F19: 0.02 | G19: Compounds monthly from Oct 2026.
... A59: Second Venue Activation Date | B59: Owner-defined | C59: date | D59: 46388 | E59: 46388 | F59: 46388 | G59: Jan 2027 activation decision.

Sheet Historical
A1: Historical — Jan to Sep 2026
A2: Observed Local Budget data through 2026-09-30. Food purchases are inventory purchasing, not consumed COGS; founder cash proxy is not economic salary.
A3: May–Sep baseline anchors the starting forecast. Revenue excludes $5,922.27 of Square advances; cash flow replaces $1,459.17 of Debt-category placeholders with settlement remittances.
A5: Observed Metric | B5: 46023 | C5: 46054 | D5: 46082 | E5: 46113 | F5: 46143 | G5: 46174 | H5: 46204 | I5: 46235 | J5: 46266 | K5: Jan–Sep 2026 Total
A6: Net Revenue | B6: 10914.69 | C6: 7379.86 | D6: 6946.7 | E6: 11396.43 | F6: 15096.45 | G6: 10443.78 | H6: 17334.09 | I6: 11466.46 | J6: 10812.43 | K6: =SUM(B6:J6) -> 101790.89
A7: Food Purchases | B7: 1815.23 | C7: 3486.39 | D7: 2630.47 | E7: 3784.26 | F7: 3526.97 | G7: 3325.58 | H7: 4312.22 | I7: 4126.8 | J7: 3326.67 | K7: =SUM(B7:J7) -> 30334.59
A8: Paid Labor | B8: 0 | C8: 40 | D8: 0 | E8: 0 | F8: 560 | G8: 2566 | H8: 1279 | I8: 1642 | J8: 190 | K8: =SUM(B8:J8) -> 6277
A9: Facility Costs | B9: 6350 | C9: 1538 | D9: 1889 | E9: 2180 | F9: 1463.33 | G9: 1525 | H9: 3849.5 | I9: 1133.83 | J9: 1179.02 | K9: =SUM(B9:J9) -> 21107.68
A10: Core Other OpEx | B10: 1137.27 | C10: 977.2 | D10: 1913.49 | E10: 1723.46 | F10: 1579.02 | G10: 2756.47 | H10: 1740.49 | I10: 1571.59 | J10: 787.2 | K10: =SUM(B10:J10) -> 14186.19
A11: Founder Cash Proxy | B11: 1089.73 | C11: 1201.3 | D11: 3677.76 | E11: 3862.46 | F11: 6572.45 | G11: 3297.57 | H11: 1432.52 | I11: 1837.94 | J11: 2020.71 | K11: =SUM(B11:J11) -> 24992.44
A12: Unclassified Transactions | B12: 30.46 | C12: 30.46 | D12: 144.02 | E12: 226.98 | F12: 568.26 | G12: 126.03 | H12: 293.93 | I12: 553.98 | J12: 393.55 | K12: =SUM(B12:J12) -> 2367.67
A13: Adjusted Cash Flow After Debt | B13: 431.43 | C13: 876.96 | D13: 2335.04 | E13: 3291.77 | F13: 1063.48 | G13: -974.88 | H13: 3225.39 | I13: 2428.11 | J13: 2103.5 | K13: =SUM(B13:J13) -> 14780.8
A16: Observed May–Sep baseline | B16: Five-month simple averages; fixed/core other OpEx anchors the editable scenario range.
A17: May–Sep Revenue Baseline | B17: 13030.64
A18: May–Sep Direct Paid Labor Baseline | B18: 1247.4
A19: May–Sep Fixed/Core Other OpEx Baseline | B19: 1686.95

Sheet Model - Downside
A1: 608 Smith Avenue — Downside Scenario
A2: Formula-driven 44-month downside case. Yellow assumptions live on Inputs; outputs below include cached values for non-calculating readers.
A3: Storefront sales are target-driven illustrations, not observed demand. Founder current cash salary and deferred repayment are separate from economic labor cost.
A5: Metric | B5: Unit | C5: Driver / interpretation | D5: 46296 | E5: 46327 | F5: 46357 | G5: 46388 | H5: 46419 | I5: 46447 | J5: 46478 | K5: 46508 | L5: 46539 | M5: 46569 | N5: 46600 | O5: 46631 | P5: 46661 | Q5: 46692 | R5: 46722 | S5: 46753 | T5: 46784 | U5: 46813 | V5: 46844 | W5: 46874 | X5: 46905 | Y5: 46935 | Z5: 46966 | AA5: 46997 | AB5: 47027 | AC5: 47058 | AD5: 47088 | AE5: 47119 | AF5: 47150 | AG5: 47178 | AH5: 47209 | AI5: 47239 | AJ5: 47270 | AK5: 47300 | AL5: 47331 | AM5: 47362 | AN5: 47392 | AO5: 47423 | AP5: 47453 | AQ5: 47484 | AR5: 47515 | AS5: 47543 | AT5: 47574 | AU5: 47604
A6: REVENUE
A7: Meal Prep Revenue | B7: $/month | C7: Smith food revenue; monthly compound growth | D7: ='Inputs'!$D$18*POWER(1+'Inputs'!$D$19,0) -> 4334.42 | E7: ='Inputs'!$D$18*POWER(1+'Inputs'!$D$19,1) -> 4334.42 | F7: ='Inputs'!$D$18*POWER(1+'Inputs'!$D$19,2) -> 4334.42 | G7: ='Inputs'!$D$18*POWER(1+'Inputs'!$D$19,3) -> 4334.42 | H7: ='Inputs'!$D$18*POWER(1+'Inputs'!$D$19,4) -> 4334.42 | I7: ='Inputs'!$D$18*POWER(1+'Inputs'!$D$19,5) -> 4334.42 | J7: ='Inputs'!$D$18*POWER(1+'Inputs'!$D$19,6) -> 4334.42 | K7: ='Inputs'!$D$18*POWER(1+'Inputs'!$D$19,7) -> 4334.42 | L7: ='Inputs'!$D$18*POWER(1+'Inputs'!$D$19,8) -> 4334.42 | M7: ='Inputs'!$D$18*POWER(1+'Inputs'!$D$19,9) -> 4334.42 | N7: ='Inputs'!$D$18*POWER(1+'Inputs'!$D$19,10) -> 4334.42 | O7: ='Inputs'!$D$18*POWER(1+'Inputs'!$D$19,11) -> 4334.42 | P7: ='Inputs'!$D$18*POWER(1+'Inputs'!$D$19,12) -> 4334.42 | Q7: ='Inputs'!$D$18*POWER(1+'Inputs'!$D$19,13) -> 4334.42 | R7: ='Inputs'!$D$18*POWER(1+'Inputs'!$D$19,14) -> 4334.42 | S7: ='Inputs'!$D$18*POWER(1+'Inputs'!$D$19,15) -> 4334.42 | T7: ='Inputs'!$D$18*POWER(1+'Inputs'!$D$19,16) -> 4334.42 | U7: ='Inputs'!$D$18*POWER(1+'Inputs'!$D$19,17) -> 4334.42 | V7: ='Inputs'!$D$18*POWER(1+'Inputs'!$D$19,18) -> 4334.42 | W7: ='Inputs'!$D$18*POWER(1+'Inputs'!$D$19,19) -> 4334.42 | X7: ='Inputs'!$D$18*POWER(1+'Inputs'!$D$19,20) -> 4334.42 | Y7: ='Inputs'!$D$18*POWER(1+'Inputs'!$D$19,21) -> 4334.42 | Z7: ='Inputs'!$D$18*POWER(1+'Inputs'!$D$19,22) -> 4334.42 | AA7: ='Inputs'!$D$18*POWER(1+'Inputs'!$D$19,23) -> 4334.42 | AB7: ='Inputs'!$D$18*POWER(1+'Inputs'!$D$19,24) -> 4334.42 | AC7: ='Inputs'!$D$18*POWER(1+'Inputs'!$D$19,25) -> 4334.42 | AD7: ='Inputs'!$D$18*POWER(1+'Inputs'!$D$19,26) -> 4334.42 | AE7: ='Inputs'!$D$18*POWER(1+'Inputs'!$D$19,27) -> 4334.42 | AF7: ='Inputs'!$D$18*POWER(1+'Inputs'!$D$19,28) -> 4334.42 | AG7: ='Inputs'!$D$18*POWER(1+'Inputs'!$D$19,29) -> 4334.42 | AH7: ='Inputs'!$D$18*POWER(1+'Inputs'!$D$19,30) -> 4334.42 | AI7: ='Inputs'!$D$18*POWER(1+'Inputs'!$D$19,31) -> 4334.42 | AJ7: ='Inputs'!$D$18*POWER(1+'Inputs'!$D$19,32) -> 4334.42 | AK7: ='Inputs'!$D$18*POWER(1+'Inputs'!$D$19,33) -> 4334.42 | AL7: ='Inputs'!$D$18*POWER(1+'Inputs'!$D$19,34) -> 4334.42 | AM7: ='Inputs'!$D$18*POWER(1+'Inputs'!$D$19,35) -> 4334.42 | AN7: ='Inputs'!$D$18*POWER(1+'Inputs'!$D$19,36) -> 4334.42 | AO7: ='Inputs'!$D$18*POWER(1+'Inputs'!$D$19,37) -> 4334.42 | AP7: ='Inputs'!$D$18*POWER(1+'Inputs'!$D$19,38) -> 4334.42 | AQ7: ='Inputs'!$D$18*POWER(1+'Inputs'!$D$19,39) -> 4334.42 | AR7: ='Inputs'!$D$18*POWER(1+'Inputs'!$D$19,40) -> 4334.42 | AS7: ='Inputs'!$D$18*POWER(1+'Inputs'!$D$19,41) -> 4334.42 | AT7: ='Inputs'!$D$18*POWER(1+'Inputs'!$D$19,42) -> 4334.42 | AU7: ='Inputs'!$D$18*POWER(1+'Inputs'!$D$19,43) -> 4334.42
A8: Frozen Pizza Revenue | B8: $/month | C8: Starting units × realized price × unit growth; produced at Hopkins | D8: ='Inputs'!$D$20*POWER(1+'Inputs'!$D$22,0)*'Inputs'!$D$21 -> 810 | E8: ='Inputs'!$D$20*POWER(1+'Inputs'!$D$22,1)*'Inputs'!$D$21 -> 810 | F8: ='Inputs'!$D$20*POWER(1+'Inputs'!$D$22,2)*'Inputs'!$D$21 -> 810 | G8: ='Inputs'!$D$20*POWER(1+'Inputs'!$D$22,3)*'Inputs'!$D$21 -> 810 | H8: ='Inputs'!$D$20*POWER(1+'Inputs'!$D$22,4)*'Inputs'!$D$21 -> 810 | I8: ='Inputs'!$D$20*POWER(1+'Inputs'!$D$22,5)*'Inputs'!$D$21 -> 810 | J8: ='Inputs'!$D$20*POWER(1+'Inputs'!$D$22,6)*'Inputs'!$D$21 -> 810 | K8: ='Inputs'!$D$20*POWER(1+'Inputs'!$D$22,7)*'Inputs'!$D$21 -> 810 | L8: ='Inputs'!$D$20*POWER(1+'Inputs'!$D$22,8)*'Inputs'!$D$21 -> 810 | M8: ='Inputs'!$D$20*POWER(1+'Inputs'!$D$22,9)*'Inputs'!$D$21 -> 810 | N8: ='Inputs'!$D$20*POWER(1+'Inputs'!$D$22,10)*'Inputs'!$D$21 -> 810 | O8: ='Inputs'!$D$20*POWER(1+'Inputs'!$D$22,11)*'Inputs'!$D$21 -> 810 | P8: ='Inputs'!$D$20*POWER(1+'Inputs'!$D$22,12)*'Inputs'!$D$21 -> 810 | Q8: ='Inputs'!$D$20*POWER(1+'Inputs'!$D$22,13)*'Inputs'!$D$21 -> 810 | R8: ='Inputs'!$D$20*POWER(1+'Inputs'!$D$22,14)*'Inputs'!$D$21 -> 810 | S8: ='Inputs'!$D$20*POWER(1+'Inputs'!$D$22,15)*'Inputs'!$D$21 -> 810 | T8: ='Inputs'!$D$20*POWER(1+'Inputs'!$D$22,16)*'Inputs'!$D$21 -> 810 | U8: ='Inputs'!$D$20*POWER(1+'Inputs'!$D$22,17)*'Inputs'!$D$21 -> 810 | V8: ='Inputs'!$D$20*POWER(1+'Inputs'!$D$22,18)*'Inputs'!$D$21 -> 810 | W8: ='Inputs'!$D$20*POWER(1+'Inputs'!$D$22,19)*'Inputs'!$D$21 -> 810 | X8: ='Inputs'!$D$20*POWER(1+'Inputs'!$D$22,20)*'Inputs'!$D$21 -> 810 | Y8: ='Inputs'!$D$20*POWER(1+'Inputs'!$D$22,21)*'Inputs'!$D$21 -> 810 | Z8: ='Inputs'!$D$20*POWER(1+'Inputs'!$D$22,22)*'Inputs'!$D$21 -> 810 | AA8: ='Inputs'!$D$20*POWER(1+'Inputs'!$D$22,23)*'Inputs'!$D$21 -> 810 | AB8: ='Inputs'!$D$20*POWER(1+'Inputs'!$D$22,24)*'Inputs'!$D$21 -> 810 | AC8: ='Inputs'!$D$20*POWER(1+'Inputs'!$D$22,25)*'Inputs'!$D$21 -> 810 | AD8: ='Inputs'!$D$20*POWER(1+'Inputs'!$D$22,26)*'Inputs'!$D$21 -> 810 | AE8: ='Inputs'!$D$20*POWER(1+'Inputs'!$D$22,27)*'Inputs'!$D$21 -> 810 | AF8: ='Inputs'!$D$20*POWER(1+'Inputs'!$D$22,28)*'Inputs'!$D$21 -> 810 | AG8: ='Inputs'!$D$20*POWER(1+'Inputs'!$D$22,29)*'Inputs'!$D$21 -> 810 | AH8: ='Inputs'!$D$20*POWER(1+'Inputs'!$D$22,30)*'Inputs'!$D$21 -> 810 | AI8: ='Inputs'!$D$20*POWER(1+'Inputs'!$D$22,31)*'Inputs'!$D$21 -> 810 | AJ8: ='Inputs'!$D$20*POWER(1+'Inputs'!$D$22,32)*'Inputs'!$D$21 -> 810 | AK8: ='Inputs'!$D$20*POWER(1+'Inputs'!$D$22,33)*'Inputs'!$D$21 -> 810 | AL8: ='Inputs'!$D$20*POWER(1+'Inputs'!$D$22,34)*'Inputs'!$D$21 -> 810 | AM8: ='Inputs'!$D$20*POWER(1+'Inputs'!$D$22,35)*'Inputs'!$D$21 -> 810 | AN8: ='Inputs'!$D$20*POWER(1+'Inputs'!$D$22,36)*'Inputs'!$D$21 -> 810 | AO8: ='Inputs'!$D$20*POWER(1+'Inputs'!$D$22,37)*'Inputs'!$D$21 -> 810 | AP8: ='Inputs'!$D$20*POWER(1+'Inputs'!$D$22,38)*'Inputs'!$D$21 -> 810 | AQ8: ='Inputs'!$D$20*POWER(1+'Inputs'!$D$22,39)*'Inputs'!$D$21 -> 810 | AR8: ='Inputs'!$D$20*POWER(1+'Inputs'!$D$22,40)*'Inputs'!$D$21 -> 810 | AS8: ='Inputs'!$D$20*POWER(1+'Inputs'!$D$22,41)*'Inputs'!$D$21 -> 810 | AT8: ='Inputs'!$D$20*POWER(1+'Inputs'!$D$22,42)*'Inputs'!$D$21 -> 810 | AU8: ='Inputs'!$D$20*POWER(1+'Inputs'!$D$22,43)*'Inputs'!$D$21 -> 810
A9: Storefront Revenue | B9: $/month | C9: Required Smith sales after meal prep and frozen pizza × six-month ramp | D9: =MAX(0,D36-D7-D8)*(IF(D$5<'Inputs'!$D$23,0,CHOOSE(MIN(7,MAX(1,(YEAR(D$5)-YEAR('Inputs'!$D$23))*12+MONTH(D$5)-MONTH('Inputs'!$D$23)+1)),'Inputs'!$D$50,'Inputs'!$D$51,'Inputs'!$D$52,'Inputs'!$D$53,'Inputs'!$D$54,'Inputs'!$D$55,'Inputs'!$D$55))) -> 0 | E9: =MAX(0,E36-E7-E8)*(IF(E$5<'Inputs'!$D$23,0,CHOOSE(MIN(7,MAX(1,(YEAR(E$5)-YEAR('Inputs'!$D$23))*12+MONTH(E$5)-MONTH('Inputs'!$D$23)+1)),'Inputs'!$D$50,'Inputs'!$D$51,'Inputs'!$D$52,'Inputs'!$D$53,'Inputs'!$D$54,'Inputs'!$D$55,'Inputs'!$D$55))) -> 0 | F9: =MAX(0,F36-F7-F8)*(IF(F$5<'Inputs'!$D$23,0,CHOOSE(MIN(7,MAX(1,(YEAR(F$5)-YEAR('Inputs'!$D$23))*12+MONTH(F$5)-MONTH('Inputs'!$D$23)+1)),'Inputs'!$D$50,'Inputs'!$D$51,'Inputs'!$D$52,'Inputs'!$D$53,'Inputs'!$D$54,'Inputs'!$D$55,'Inputs'!$D$55))) -> 0 | G9: =MAX(0,G36-G7-G8)*(IF(G$5<'Inputs'!$D$23,0,CHOOSE(MIN(7,MAX(1,(YEAR(G$5)-YEAR('Inputs'!$D$23))*12+MONTH(G$5)-MONTH('Inputs'!$D$23)+1)),'Inputs'!$D$50,'Inputs'!$D$51,'Inputs'!$D$52,'Inputs'!$D$53,'Inputs'!$D$54,'Inputs'!$D$55,'Inputs'!$D$55))) -> 0 | H9: =MAX(0,H36-H7-H8)*(IF(H$5<'Inputs'!$D$23,0,CHOOSE(MIN(7,MAX(1,(YEAR(H$5)-YEAR('Inputs'!$D$23))*12+MONTH(H$5)-MONTH('Inputs'!$D$23)+1)),'Inputs'!$D$50,'Inputs'!$D$51,'Inputs'!$D$52,'Inputs'!$D$53,'Inputs'!$D$54,'Inputs'!$D$55,'Inputs'!$D$55))) -> 0 | I9: =MAX(0,I36-I7-I8)*(IF(I$5<'Inputs'!$D$23,0,CHOOSE(MIN(7,MAX(1,(YEAR(I$5)-YEAR('Inputs'!$D$23))*12+MONTH(I$5)-MONTH('Inputs'!$D$23)+1)),'Inputs'!$D$50,'Inputs'!$D$51,'Inputs'!$D$52,'Inputs'!$D$53,'Inputs'!$D$54,'Inputs'!$D$55,'Inputs'!$D$55))) -> 0 | J9: =MAX(0,J36-J7-J8)*(IF(J$5<'Inputs'!$D$23,0,CHOOSE(MIN(7,MAX(1,(YEAR(J$5)-YEAR('Inputs'!$D$23))*12+MONTH(J$5)-MONTH('Inputs'!$D$23)+1)),'Inputs'!$D$50,'Inputs'!$D$51,'Inputs'!$D$52,'Inputs'!$D$53,'Inputs'!$D$54,'Inputs'!$D$55,'Inputs'!$D$55))) -> 0 | K9: =MAX(0,K36-K7-K8)*(IF(K$5<'Inputs'!$D$23,0,CHOOSE(MIN(7,MAX(1,(YEAR(K$5)-YEAR('Inputs'!$D$23))*12+MONTH(K$5)-MONTH('Inputs'!$D$23)+1)),'Inputs'!$D$50,'Inputs'!$D$51,'Inputs'!$D$52,'Inputs'!$D$53,'Inputs'!$D$54,'Inputs'!$D$55,'Inputs'!$D$55))) -> 0 | ... AU9: =MAX(0,AU36-AU7-AU8)*(IF(AU$5<'Inputs'!$D$23,0,CHOOSE(MIN(7,MAX(1,(YEAR(AU$5)-YEAR('Inputs'!$D$23))*12+MONTH(AU$5)-MONTH('Inputs'!$D$23)+1)),'Inputs'!$D$50,'Inputs'!$D$51,'Inputs'!$D$52,'Inputs'!$D$53,'Inputs'!$D$54,'Inputs'!$D$55,'Inputs'!$D$55))) -> 48485.58
A10: Smith Revenue | B10: $/month | C10: Meal prep + frozen pizza + storefront | D10: =SUM(D7:D9) -> 5144.42 | E10: =SUM(E7:E9) -> 5144.42 | F10: =SUM(F7:F9) -> 5144.42 | G10: =SUM(G7:G9) -> 5144.42 | H10: =SUM(H7:H9) -> 5144.42 | I10: =SUM(I7:I9) -> 5144.42 | J10: =SUM(J7:J9) -> 5144.42 | K10: =SUM(K7:K9) -> 5144.42 | ... AU10: =SUM(AU7:AU9) -> 53630
A11: Airbnb Revenue | B11: $/month | C11: Nonfood revenue at the second venue | D11: ='Inputs'!$D$11*'Inputs'!$D$48*(IF(D$5<'Inputs'!$D$57,0,IF(D$5<='Inputs'!$D$58,'Inputs'!$D$10,IF(D$5>='Inputs'!$D$59,'Inputs'!$D$9,0)))) -> 1800 | E11: ='Inputs'!$D$11*'Inputs'!$D$48*(IF(E$5<'Inputs'!$D$57,0,IF(E$5<='Inputs'!$D$58,'Inputs'!$D$10,IF(E$5>='Inputs'!$D$59,'Inputs'!$D$9,0)))) -> 1800 | F11: ='Inputs'!$D$11*'Inputs'!$D$48*(IF(F$5<'Inputs'!$D$57,0,IF(F$5<='Inputs'!$D$58,'Inputs'!$D$10,IF(F$5>='Inputs'!$D$59,'Inputs'!$D$9,0)))) -> 1800 | G11: ='Inputs'!$D$11*'Inputs'!$D$48*(IF(G$5<'Inputs'!$D$57,0,IF(G$5<='Inputs'!$D$58,'Inputs'!$D$10,IF(G$5>='Inputs'!$D$59,'Inputs'!$D$9,0)))) -> 0 | H11: ='Inputs'!$D$11*'Inputs'!$D$48*(IF(H$5<'Inputs'!$D$57,0,IF(H$5<='Inputs'!$D$58,'Inputs'!$D$10,IF(H$5>='Inputs'!$D$59,'Inputs'!$D$9,0)))) -> 0 | I11: ='Inputs'!$D$11*'Inputs'!$D$48*(IF(I$5<'Inputs'!$D$57,0,IF(I$5<='Inputs'!$D$58,'Inputs'!$D$10,IF(I$5>='Inputs'!$D$59,'Inputs'!$D$9,0)))) -> 0 | J11: ='Inputs'!$D$11*'Inputs'!$D$48*(IF(J$5<'Inputs'!$D$57,0,IF(J$5<='Inputs'!$D$58,'Inputs'!$D$10,IF(J$5>='Inputs'!$D$59,'Inputs'!$D$9,0)))) -> 0 | K11: ='Inputs'!$D$11*'Inputs'!$D$48*(IF(K$5<'Inputs'!$D$57,0,IF(K$5<='Inputs'!$D$58,'Inputs'!$D$10,IF(K$5>='Inputs'!$D$59,'Inputs'!$D$9,0)))) -> 0 | ... AU11: ='Inputs'!$D$11*'Inputs'!$D$48*(IF(AU$5<'Inputs'!$D$57,0,IF(AU$5<='Inputs'!$D$58,'Inputs'!$D$10,IF(AU$5>='Inputs'!$D$59,'Inputs'!$D$9,0)))) -> 0
A12: Small Events Revenue | B12: $/month | C12: Gross small-event revenue | D12: ='Inputs'!$D$13*'Inputs'!$D$14*(IF(D$5<'Inputs'!$D$57,0,IF(D$5<='Inputs'!$D$58,'Inputs'!$D$10,IF(D$5>='Inputs'!$D$59,'Inputs'!$D$9,0)))) -> 1050 | E12: ='Inputs'!$D$13*'Inputs'!$D$14*(IF(E$5<'Inputs'!$D$57,0,IF(E$5<='Inputs'!$D$58,'Inputs'!$D$10,IF(E$5>='Inputs'!$D$59,'Inputs'!$D$9,0)))) -> 1050 | F12: ='Inputs'!$D$13*'Inputs'!$D$14*(IF(F$5<'Inputs'!$D$57,0,IF(F$5<='Inputs'!$D$58,'Inputs'!$D$10,IF(F$5>='Inputs'!$D$59,'Inputs'!$D$9,0)))) -> 1050 | G12: ='Inputs'!$D$13*'Inputs'!$D$14*(IF(G$5<'Inputs'!$D$57,0,IF(G$5<='Inputs'!$D$58,'Inputs'!$D$10,IF(G$5>='Inputs'!$D$59,'Inputs'!$D$9,0)))) -> 0 | H12: ='Inputs'!$D$13*'Inputs'!$D$14*(IF(H$5<'Inputs'!$D$57,0,IF(H$5<='Inputs'!$D$58,'Inputs'!$D$10,IF(H$5>='Inputs'!$D$59,'Inputs'!$D$9,0)))) -> 0 | I12: ='Inputs'!$D$13*'Inputs'!$D$14*(IF(I$5<'Inputs'!$D$57,0,IF(I$5<='Inputs'!$D$58,'Inputs'!$D$10,IF(I$5>='Inputs'!$D$59,'Inputs'!$D$9,0)))) -> 0 | J12: ='Inputs'!$D$13*'Inputs'!$D$14*(IF(J$5<'Inputs'!$D$57,0,IF(J$5<='Inputs'!$D$58,'Inputs'!$D$10,IF(J$5>='Inputs'!$D$59,'Inputs'!$D$9,0)))) -> 0 | K12: ='Inputs'!$D$13*'Inputs'!$D$14*(IF(K$5<'Inputs'!$D$57,0,IF(K$5<='Inputs'!$D$58,'Inputs'!$D$10,IF(K$5>='Inputs'!$D$59,'Inputs'!$D$9,0)))) -> 0 | ... AU12: ='Inputs'!$D$13*'Inputs'!$D$14*(IF(AU$5<'Inputs'!$D$57,0,IF(AU$5<='Inputs'!$D$58,'Inputs'!$D$10,IF(AU$5>='Inputs'!$D$59,'Inputs'!$D$9,0)))) -> 0
A13: Personal Chef Revenue | B13: $/month | C13: Food revenue from packages at the second venue | D13: ='Inputs'!$D$16*'Inputs'!$D$17*(IF(D$5<'Inputs'!$D$57,0,IF(D$5<='Inputs'!$D$58,'Inputs'!$D$10,IF(D$5>='Inputs'!$D$59,'Inputs'!$D$9,0)))) -> 400 | E13: ='Inputs'!$D$16*'Inputs'!$D$17*(IF(E$5<'Inputs'!$D$57,0,IF(E$5<='Inputs'!$D$58,'Inputs'!$D$10,IF(E$5>='Inputs'!$D$59,'Inputs'!$D$9,0)))) -> 400 | F13: ='Inputs'!$D$16*'Inputs'!$D$17*(IF(F$5<'Inputs'!$D$57,0,IF(F$5<='Inputs'!$D$58,'Inputs'!$D$10,IF(F$5>='Inputs'!$D$59,'Inputs'!$D$9,0)))) -> 400 | G13: ='Inputs'!$D$16*'Inputs'!$D$17*(IF(G$5<'Inputs'!$D$57,0,IF(G$5<='Inputs'!$D$58,'Inputs'!$D$10,IF(G$5>='Inputs'!$D$59,'Inputs'!$D$9,0)))) -> 0 | H13: ='Inputs'!$D$16*'Inputs'!$D$17*(IF(H$5<'Inputs'!$D$57,0,IF(H$5<='Inputs'!$D$58,'Inputs'!$D$10,IF(H$5>='Inputs'!$D$59,'Inputs'!$D$9,0)))) -> 0 | I13: ='Inputs'!$D$16*'Inputs'!$D$17*(IF(I$5<'Inputs'!$D$57,0,IF(I$5<='Inputs'!$D$58,'Inputs'!$D$10,IF(I$5>='Inputs'!$D$59,'Inputs'!$D$9,0)))) -> 0 | J13: ='Inputs'!$D$16*'Inputs'!$D$17*(IF(J$5<'Inputs'!$D$57,0,IF(J$5<='Inputs'!$D$58,'Inputs'!$D$10,IF(J$5>='Inputs'!$D$59,'Inputs'!$D$9,0)))) -> 0 | K13: ='Inputs'!$D$16*'Inputs'!$D$17*(IF(K$5<'Inputs'!$D$57,0,IF(K$5<='Inputs'!$D$58,'Inputs'!$D$10,IF(K$5>='Inputs'!$D$59,'Inputs'!$D$9,0)))) -> 0 | ... AU13: ='Inputs'!$D$16*'Inputs'!$D$17*(IF(AU$5<'Inputs'!$D$57,0,IF(AU$5<='Inputs'!$D$58,'Inputs'!$D$10,IF(AU$5>='Inputs'!$D$59,'Inputs'!$D$9,0)))) -> 0
A14: Second Venue Revenue | B14: $/month | C14: Airbnb + small events + personal chef | D14: =SUM(D11:D13) -> 3250 | E14: =SUM(E11:E13) -> 3250 | F14: =SUM(F11:F13) -> 3250 | G14: =SUM(G11:G13) -> 0 | H14: =SUM(H11:H13) -> 0 | I14: =SUM(I11:I13) -> 0 | J14: =SUM(J11:J13) -> 0 | K14: =SUM(K11:K13) -> 0 | ... AU14: =SUM(AU11:AU13) -> 0
A15: Total Revenue | B15: $/month | C15: Smith + second venue | D15: =D10+D14 -> 8394.42 | E15: =E10+E14 -> 8394.42 | F15: =F10+F14 -> 8394.42 | G15: =G10+G14 -> 5144.42 | H15: =H10+H14 -> 5144.42 | I15: =I10+I14 -> 5144.42 | J15: =J10+J14 -> 5144.42 | K15: =K10+K14 -> 5144.42 | ... AU15: =AU10+AU14 -> 53630
A16: Food Revenue | B16: $/month | C16: Smith + event food component + personal chef | D16: =D10+'Inputs'!$D$13*'Inputs'!$D$15*(IF(D$5<'Inputs'!$D$57,0,IF(D$5<='Inputs'!$D$58,'Inputs'!$D$10,IF(D$5>='Inputs'!$D$59,'Inputs'!$D$9,0))))+D13 -> 6219.42 | E16: =E10+'Inputs'!$D$13*'Inputs'!$D$15*(IF(E$5<'Inputs'!$D$57,0,IF(E$5<='Inputs'!$D$58,'Inputs'!$D$10,IF(E$5>='Inputs'!$D$59,'Inputs'!$D$9,0))))+E13 -> 6219.42 | F16: =F10+'Inputs'!$D$13*'Inputs'!$D$15*(IF(F$5<'Inputs'!$D$57,0,IF(F$5<='Inputs'!$D$58,'Inputs'!$D$10,IF(F$5>='Inputs'!$D$59,'Inputs'!$D$9,0))))+F13 -> 6219.42 | G16: =G10+'Inputs'!$D$13*'Inputs'!$D$15*(IF(G$5<'Inputs'!$D$57,0,IF(G$5<='Inputs'!$D$58,'Inputs'!$D$10,IF(G$5>='Inputs'!$D$59,'Inputs'!$D$9,0))))+G13 -> 5144.42 | H16: =H10+'Inputs'!$D$13*'Inputs'!$D$15*(IF(H$5<'Inputs'!$D$57,0,IF(H$5<='Inputs'!$D$58,'Inputs'!$D$10,IF(H$5>='Inputs'!$D$59,'Inputs'!$D$9,0))))+H13 -> 5144.42 | I16: =I10+'Inputs'!$D$13*'Inputs'!$D$15*(IF(I$5<'Inputs'!$D$57,0,IF(I$5<='Inputs'!$D$58,'Inputs'!$D$10,IF(I$5>='Inputs'!$D$59,'Inputs'!$D$9,0))))+I13 -> 5144.42 | J16: =J10+'Inputs'!$D$13*'Inputs'!$D$15*(IF(J$5<'Inputs'!$D$57,0,IF(J$5<='Inputs'!$D$58,'Inputs'!$D$10,IF(J$5>='Inputs'!$D$59,'Inputs'!$D$9,0))))+J13 -> 5144.42 | K16: =K10+'Inputs'!$D$13*'Inputs'!$D$15*(IF(K$5<'Inputs'!$D$57,0,IF(K$5<='Inputs'!$D$58,'Inputs'!$D$10,IF(K$5>='Inputs'!$D$59,'Inputs'!$D$9,0))))+K13 -> 5144.42 | ... AU16: =AU10+'Inputs'!$D$13*'Inputs'!$D$15*(IF(AU$5<'Inputs'!$D$57,0,IF(AU$5<='Inputs'!$D$58,'Inputs'!$D$10,IF(AU$5>='Inputs'!$D$59,'Inputs'!$D$9,0))))+AU13 -> 53630
A17: COST OF SALES & LABOR
A18: Food COGS | B18: $/month | C18: Applied only to food revenue | D18: =D16*'Inputs'!$D$27 -> 1368.2724 | E18: =E16*'Inputs'!$D$27 -> 1368.2724 | F18: =F16*'Inputs'!$D$27 -> 1368.2724 | G18: =G16*'Inputs'!$D$27 -> 1131.7724 | H18: =H16*'Inputs'!$D$27 -> 1131.7724 | I18: =I16*'Inputs'!$D$27 -> 1131.7724 | J18: =J16*'Inputs'!$D$27 -> 1131.7724 | K18: =K16*'Inputs'!$D$27 -> 1131.7724 | ... AU18: =AU16*'Inputs'!$D$27 -> 11798.6
A19: Food Cost % | B19: % revenue | C19: Food COGS ÷ food revenue | D19: =IFERROR(D18/D16,0) -> 0.22 | E19: =IFERROR(E18/E16,0) -> 0.22 | F19: =IFERROR(F18/F16,0) -> 0.22 | G19: =IFERROR(G18/G16,0) -> 0.22 | H19: =IFERROR(H18/H16,0) -> 0.22 | I19: =IFERROR(I18/I16,0) -> 0.22 | J19: =IFERROR(J18/J16,0) -> 0.22 | K19: =IFERROR(K18/K16,0) -> 0.22 | ... AU19: =IFERROR(AU18/AU16,0) -> 0.22
A20: Venue Variable Cost | B20: $/month | C20: Applied only to Airbnb revenue | D20: =D11*'Inputs'!$D$12 -> 450 | E20: =E11*'Inputs'!$D$12 -> 450 | F20: =F11*'Inputs'!$D$12 -> 450 | G20: =G11*'Inputs'!$D$12 -> 0 | H20: =H11*'Inputs'!$D$12 -> 0 | I20: =I11*'Inputs'!$D$12 -> 0 | J20: =J11*'Inputs'!$D$12 -> 0 | K20: =K11*'Inputs'!$D$12 -> 0 | ... AU20: =AU11*'Inputs'!$D$12 -> 0
A21: Packaging & Delivery | B21: $/month | C21: Applied to food revenue | D21: =D16*'Inputs'!$D$37 -> 248.7768 | E21: =E16*'Inputs'!$D$37 -> 248.7768 | F21: =F16*'Inputs'!$D$37 -> 248.7768 | G21: =G16*'Inputs'!$D$37 -> 205.7768 | H21: =H16*'Inputs'!$D$37 -> 205.7768 | I21: =I16*'Inputs'!$D$37 -> 205.7768 | J21: =J16*'Inputs'!$D$37 -> 205.7768 | K21: =K16*'Inputs'!$D$37 -> 205.7768 | ... AU21: =AU16*'Inputs'!$D$37 -> 2145.2
A22: Direct Paid Labor | B22: $/month | C22: Phase rate × total revenue | D22: =D15*(IF(D$5<'Inputs'!$D$23,'Inputs'!$D$28,IF(D$5<EDATE('Inputs'!$D$23,6),'Inputs'!$D$29,'Inputs'!$D$30))) -> 1259.163 | E22: =E15*(IF(E$5<'Inputs'!$D$23,'Inputs'!$D$28,IF(E$5<EDATE('Inputs'!$D$23,6),'Inputs'!$D$29,'Inputs'!$D$30))) -> 1259.163 | F22: =F15*(IF(F$5<'Inputs'!$D$23,'Inputs'!$D$28,IF(F$5<EDATE('Inputs'!$D$23,6),'Inputs'!$D$29,'Inputs'!$D$30))) -> 1259.163 | G22: =G15*(IF(G$5<'Inputs'!$D$23,'Inputs'!$D$28,IF(G$5<EDATE('Inputs'!$D$23,6),'Inputs'!$D$29,'Inputs'!$D$30))) -> 771.663 | H22: =H15*(IF(H$5<'Inputs'!$D$23,'Inputs'!$D$28,IF(H$5<EDATE('Inputs'!$D$23,6),'Inputs'!$D$29,'Inputs'!$D$30))) -> 771.663 | I22: =I15*(IF(I$5<'Inputs'!$D$23,'Inputs'!$D$28,IF(I$5<EDATE('Inputs'!$D$23,6),'Inputs'!$D$29,'Inputs'!$D$30))) -> 771.663 | J22: =J15*(IF(J$5<'Inputs'!$D$23,'Inputs'!$D$28,IF(J$5<EDATE('Inputs'!$D$23,6),'Inputs'!$D$29,'Inputs'!$D$30))) -> 771.663 | K22: =K15*(IF(K$5<'Inputs'!$D$23,'Inputs'!$D$28,IF(K$5<EDATE('Inputs'!$D$23,6),'Inputs'!$D$29,'Inputs'!$D$30))) -> 771.663 | ... AU22: =AU15*(IF(AU$5<'Inputs'!$D$23,'Inputs'!$D$28,IF(AU$5<EDATE('Inputs'!$D$23,6),'Inputs'!$D$29,'Inputs'!$D$30))) -> 10726
A23: Founder Economic Salary | B23: $/month | C23: Catherine + Weston combined economic compensation | D23: ='Inputs'!$D$32 -> 7500 | E23: ='Inputs'!$D$32 -> 7500 | F23: ='Inputs'!$D$32 -> 7500 | G23: ='Inputs'!$D$32 -> 7500 | H23: ='Inputs'!$D$32 -> 7500 | I23: ='Inputs'!$D$32 -> 7500 | J23: ='Inputs'!$D$32 -> 7500 | K23: ='Inputs'!$D$32 -> 7500 | ... AU23: ='Inputs'!$D$32 -> 7500
A24: Direct Payroll Burden | B24: $/month | C24: Burden on direct paid labor | D24: =D22*'Inputs'!$D$31 -> 151.09956 | E24: =E22*'Inputs'!$D$31 -> 151.09956 | F24: =F22*'Inputs'!$D$31 -> 151.09956 | G24: =G22*'Inputs'!$D$31 -> 92.59956 | H24: =H22*'Inputs'!$D$31 -> 92.59956 | I24: =I22*'Inputs'!$D$31 -> 92.59956 | J24: =J22*'Inputs'!$D$31 -> 92.59956 | K24: =K22*'Inputs'!$D$31 -> 92.59956 | ... AU24: =AU22*'Inputs'!$D$31 -> 1287.12
A25: Total Labor | B25: $/month | C25: Direct labor + founder economic compensation + burden | D25: =SUM(D22,D23,D24) -> 8910.2626 | E25: =SUM(E22,E23,E24) -> 8910.2626 | F25: =SUM(F22,F23,F24) -> 8910.2626 | G25: =SUM(G22,G23,G24) -> 8364.2626 | H25: =SUM(H22,H23,H24) -> 8364.2626 | I25: =SUM(I22,I23,I24) -> 8364.2626 | J25: =SUM(J22,J23,J24) -> 8364.2626 | K25: =SUM(K22,K23,K24) -> 8364.2626 | ... AU25: =SUM(AU22,AU23,AU24) -> 19513.12
A26: Total Labor % | B26: % revenue | C26: Total labor ÷ total revenue | D26: =IFERROR(D25/D15,0) -> 1.0614506 | E26: =IFERROR(E25/E15,0) -> 1.0614506 | F26: =IFERROR(F25/F15,0) -> 1.0614506 | G26: =IFERROR(G25/G15,0) -> 1.6258903 | H26: =IFERROR(H25/H15,0) -> 1.6258903 | I26: =IFERROR(I25/I15,0) -> 1.6258903 | J26: =IFERROR(J25/J15,0) -> 1.6258903 | K26: =IFERROR(K25/K15,0) -> 1.6258903 | ... AU26: =IFERROR(AU25/AU15,0) -> 0.3638471
A27: OCCUPANCY & REQUIRED SALES
A28: Smith Rent & NNN | B28: $/month | C28: Owner-provided stepped rent schedule | D28: =IF(D$5<DATE(2026,10,1),'Inputs'!$D$41,IF(D$5<DATE(2027,1,1),'Inputs'!$D$42,IF(D$5<DATE(2027,6,1),'Inputs'!$D$43,IF(D$5<DATE(2028,1,1),'Inputs'!$D$44,'Inputs'!$D$45)))) -> 1800 | E28: =IF(E$5<DATE(2026,10,1),'Inputs'!$D$41,IF(E$5<DATE(2027,1,1),'Inputs'!$D$42,IF(E$5<DATE(2027,6,1),'Inputs'!$D$43,IF(E$5<DATE(2028,1,1),'Inputs'!$D$44,'Inputs'!$D$45)))) -> 1800 | F28: =IF(F$5<DATE(2026,10,1),'Inputs'!$D$41,IF(F$5<DATE(2027,1,1),'Inputs'!$D$42,IF(F$5<DATE(2027,6,1),'Inputs'!$D$43,IF(F$5<DATE(2028,1,1),'Inputs'!$D$44,'Inputs'!$D$45)))) -> 1800 | G28: =IF(G$5<DATE(2026,10,1),'Inputs'!$D$41,IF(G$5<DATE(2027,1,1),'Inputs'!$D$42,IF(G$5<DATE(2027,6,1),'Inputs'!$D$43,IF(G$5<DATE(2028,1,1),'Inputs'!$D$44,'Inputs'!$D$45)))) -> 2600 | H28: =IF(H$5<DATE(2026,10,1),'Inputs'!$D$41,IF(H$5<DATE(2027,1,1),'Inputs'!$D$42,IF(H$5<DATE(2027,6,1),'Inputs'!$D$43,IF(H$5<DATE(2028,1,1),'Inputs'!$D$44,'Inputs'!$D$45)))) -> 2600 | I28: =IF(I$5<DATE(2026,10,1),'Inputs'!$D$41,IF(I$5<DATE(2027,1,1),'Inputs'!$D$42,IF(I$5<DATE(2027,6,1),'Inputs'!$D$43,IF(I$5<DATE(2028,1,1),'Inputs'!$D$44,'Inputs'!$D$45)))) -> 2600 | J28: =IF(J$5<DATE(2026,10,1),'Inputs'!$D$41,IF(J$5<DATE(2027,1,1),'Inputs'!$D$42,IF(J$5<DATE(2027,6,1),'Inputs'!$D$43,IF(J$5<DATE(2028,1,1),'Inputs'!$D$44,'Inputs'!$D$45)))) -> 2600 | K28: =IF(K$5<DATE(2026,10,1),'Inputs'!$D$41,IF(K$5<DATE(2027,1,1),'Inputs'!$D$42,IF(K$5<DATE(2027,6,1),'Inputs'!$D$43,IF(K$5<DATE(2028,1,1),'Inputs'!$D$44,'Inputs'!$D$45)))) -> 2600 | ... AU28: =IF(AU$5<DATE(2026,10,1),'Inputs'!$D$41,IF(AU$5<DATE(2027,1,1),'Inputs'!$D$42,IF(AU$5<DATE(2027,6,1),'Inputs'!$D$43,IF(AU$5<DATE(2028,1,1),'Inputs'!$D$44,'Inputs'!$D$45)))) -> 3963
A29: Smith Utilities | B29: $/month | C29: Begins on the editable transfer date | D29: =IF(D$5>='Inputs'!$D$46,'Inputs'!$D$8,0) -> 0 | E29: =IF(E$5>='Inputs'!$D$46,'Inputs'!$D$8,0) -> 0 | F29: =IF(F$5>='Inputs'!$D$46,'Inputs'!$D$8,0) -> 0 | G29: =IF(G$5>='Inputs'!$D$46,'Inputs'!$D$8,0) -> 0 | H29: =IF(H$5>='Inputs'!$D$46,'Inputs'!$D$8,0) -> 0 | I29: =IF(I$5>='Inputs'!$D$46,'Inputs'!$D$8,0) -> 1400 | J29: =IF(J$5>='Inputs'!$D$46,'Inputs'!$D$8,0) -> 1400 | K29: =IF(K$5>='Inputs'!$D$46,'Inputs'!$D$8,0) -> 1400 | ... AU29: =IF(AU$5>='Inputs'!$D$46,'Inputs'!$D$8,0) -> 1400
A30: Smith Occupancy Cost | B30: $/month | C30: Smith rent + utilities | D30: =SUM(D28:D29) -> 1800 | E30: =SUM(E28:E29) -> 1800 | F30: =SUM(F28:F29) -> 1800 | G30: =SUM(G28:G29) -> 2600 | H30: =SUM(H28:H29) -> 2600 | I30: =SUM(I28:I29) -> 4000 | J30: =SUM(J28:J29) -> 4000 | K30: =SUM(K28:K29) -> 4000 | ... AU30: =SUM(AU28:AU29) -> 5363
A31: Second Venue Rent | B31: $/month | C31: Conditional on post-trial activation | D31: =IF(D$5>='Inputs'!$D$59,'Inputs'!$D$9*'Inputs'!$D$47,0) -> 0 | E31: =IF(E$5>='Inputs'!$D$59,'Inputs'!$D$9*'Inputs'!$D$47,0) -> 0 | F31: =IF(F$5>='Inputs'!$D$59,'Inputs'!$D$9*'Inputs'!$D$47,0) -> 0 | G31: =IF(G$5>='Inputs'!$D$59,'Inputs'!$D$9*'Inputs'!$D$47,0) -> 0 | H31: =IF(H$5>='Inputs'!$D$59,'Inputs'!$D$9*'Inputs'!$D$47,0) -> 0 | I31: =IF(I$5>='Inputs'!$D$59,'Inputs'!$D$9*'Inputs'!$D$47,0) -> 0 | J31: =IF(J$5>='Inputs'!$D$59,'Inputs'!$D$9*'Inputs'!$D$47,0) -> 0 | K31: =IF(K$5>='Inputs'!$D$59,'Inputs'!$D$9*'Inputs'!$D$47,0) -> 0 | ... AU31: =IF(AU$5>='Inputs'!$D$59,'Inputs'!$D$9*'Inputs'!$D$47,0) -> 0
A32: Hopkins Admin | B32: $/month | C32: Ongoing Hopkins facility/admin charge | D32: ='Inputs'!$D$49 -> 150 | E32: ='Inputs'!$D$49 -> 150 | F32: ='Inputs'!$D$49 -> 150 | G32: ='Inputs'!$D$49 -> 150 | H32: ='Inputs'!$D$49 -> 150 | I32: ='Inputs'!$D$49 -> 150 | J32: ='Inputs'!$D$49 -> 150 | K32: ='Inputs'!$D$49 -> 150 | ... AU32: ='Inputs'!$D$49 -> 150
A33: Total Occupancy Cost | B33: $/month | C33: Smith + second venue + Hopkins | D33: =SUM(D30,D31,D32) -> 1950 | E33: =SUM(E30,E31,E32) -> 1950 | F33: =SUM(F30,F31,F32) -> 1950 | G33: =SUM(G30,G31,G32) -> 2750 | H33: =SUM(H30,H31,H32) -> 2750 | I33: =SUM(I30,I31,I32) -> 4150 | J33: =SUM(J30,J31,J32) -> 4150 | K33: =SUM(K30,K31,K32) -> 4150 | ... AU33: =SUM(AU30,AU31,AU32) -> 5513
A34: Consolidated Occupancy % | B34: % revenue | C34: Total occupancy ÷ total revenue | D34: =IFERROR(D33/D15,0) -> 0.23229717 | E34: =IFERROR(E33/E15,0) -> 0.23229717 | F34: =IFERROR(F33/F15,0) -> 0.23229717 | G34: =IFERROR(G33/G15,0) -> 0.53455978 | H34: =IFERROR(H33/H15,0) -> 0.53455978 | I34: =IFERROR(I33/I15,0) -> 0.8066993 | J34: =IFERROR(J33/J15,0) -> 0.8066993 | K34: =IFERROR(K33/K15,0) -> 0.8066993 | ... AU34: =IFERROR(AU33/AU15,0) -> 0.10279694
A35: Smith Occupancy % | B35: % revenue | C35: Smith occupancy ÷ Smith revenue | D35: =IFERROR(D30/D10,0) -> 0.34989367 | E35: =IFERROR(E30/E10,0) -> 0.34989367 | F35: =IFERROR(F30/F10,0) -> 0.34989367 | G35: =IFERROR(G30/G10,0) -> 0.50540197 | H35: =IFERROR(H30/H10,0) -> 0.50540197 | I35: =IFERROR(I30/I10,0) -> 0.77754149 | J35: =IFERROR(J30/J10,0) -> 0.77754149 | K35: =IFERROR(K30/K10,0) -> 0.77754149 | ... AU35: =IFERROR(AU30/AU10,0) -> 0.1
A36: Required Smith Revenue | B36: $/month | C36: Smith occupancy ÷ target ratio | D36: =D30/'Inputs'!$D$24 -> 18000 | E36: =E30/'Inputs'!$D$24 -> 18000 | F36: =F30/'Inputs'!$D$24 -> 18000 | G36: =G30/'Inputs'!$D$24 -> 26000 | H36: =H30/'Inputs'!$D$24 -> 26000 | I36: =I30/'Inputs'!$D$24 -> 40000 | J36: =J30/'Inputs'!$D$24 -> 40000 | K36: =K30/'Inputs'!$D$24 -> 40000 | ... AU36: =AU30/'Inputs'!$D$24 -> 53630
A37: Smith Revenue Gap / (Surplus) | B37: $/month | C37: Required less modeled Smith revenue | D37: =D36-D10 -> 12855.58 | E37: =E36-E10 -> 12855.58 | F37: =F36-F10 -> 12855.58 | G37: =G36-G10 -> 20855.58 | H37: =H36-H10 -> 20855.58 | I37: =I36-I10 -> 34855.58 | J37: =J36-J10 -> 34855.58 | K37: =K36-K10 -> 34855.58 | ... AU37: =AU36-AU10 -> 0
A38: Required Storefront Transactions / Day | B38: transactions | C38: Required storefront sales ÷ ticket ÷ open days | D38: =MAX(0,D36-D7-D8)/('Inputs'!$D$25*'Inputs'!$D$26) -> 35.709944 | E38: =MAX(0,E36-E7-E8)/('Inputs'!$D$25*'Inputs'!$D$26) -> 35.709944 | F38: =MAX(0,F36-F7-F8)/('Inputs'!$D$25*'Inputs'!$D$26) -> 35.709944 | G38: =MAX(0,G36-G7-G8)/('Inputs'!$D$25*'Inputs'!$D$26) -> 57.932167 | H38: =MAX(0,H36-H7-H8)/('Inputs'!$D$25*'Inputs'!$D$26) -> 57.932167 | I38: =MAX(0,I36-I7-I8)/('Inputs'!$D$25*'Inputs'!$D$26) -> 96.821056 | J38: =MAX(0,J36-J7-J8)/('Inputs'!$D$25*'Inputs'!$D$26) -> 96.821056 | K38: =MAX(0,K36-K7-K8)/('Inputs'!$D$25*'Inputs'!$D$26) -> 96.821056 | ... AU38: =MAX(0,AU36-AU7-AU8)/('Inputs'!$D$25*'Inputs'!$D$26) -> 134.68217
A39: OPERATING RESULT & CASH
A40: Payment Processing | B40: $/month | C40: 3% of revenue other than Airbnb | D40: ='Inputs'!$D$38*(D15-D11) -> 197.8326 | E40: ='Inputs'!$D$38*(E15-E11) -> 197.8326 | F40: ='Inputs'!$D$38*(F15-F11) -> 197.8326 | G40: ='Inputs'!$D$38*(G15-G11) -> 154.3326 | H40: ='Inputs'!$D$38*(H15-H11) -> 154.3326 | I40: ='Inputs'!$D$38*(I15-I11) -> 154.3326 | J40: ='Inputs'!$D$38*(J15-J11) -> 154.3326 | K40: ='Inputs'!$D$38*(K15-K11) -> 154.3326 | ... AU40: ='Inputs'!$D$38*(AU15-AU11) -> 1608.9
A41: Fixed Other OpEx | B41: $/month | C41: 3% inflation on each model-year anniversary | D41: ='Inputs'!$D$39*POWER(1+'Inputs'!$D$56,INT(((YEAR(D$5)-YEAR($D$5))*12+MONTH(D$5)-MONTH($D$5))/12)) -> 1855.65 | E41: ='Inputs'!$D$39*POWER(1+'Inputs'!$D$56,INT(((YEAR(E$5)-YEAR($D$5))*12+MONTH(E$5)-MONTH($D$5))/12)) -> 1855.65 | F41: ='Inputs'!$D$39*POWER(1+'Inputs'!$D$56,INT(((YEAR(F$5)-YEAR($D$5))*12+MONTH(F$5)-MONTH($D$5))/12)) -> 1855.65 | G41: ='Inputs'!$D$39*POWER(1+'Inputs'!$D$56,INT(((YEAR(G$5)-YEAR($D$5))*12+MONTH(G$5)-MONTH($D$5))/12)) -> 1855.65 | H41: ='Inputs'!$D$39*POWER(1+'Inputs'!$D$56,INT(((YEAR(H$5)-YEAR($D$5))*12+MONTH(H$5)-MONTH($D$5))/12)) -> 1855.65 | I41: ='Inputs'!$D$39*POWER(1+'Inputs'!$D$56,INT(((YEAR(I$5)-YEAR($D$5))*12+MONTH(I$5)-MONTH($D$5))/12)) -> 1855.65 | J41: ='Inputs'!$D$39*POWER(1+'Inputs'!$D$56,INT(((YEAR(J$5)-YEAR($D$5))*12+MONTH(J$5)-MONTH($D$5))/12)) -> 1855.65 | K41: ='Inputs'!$D$39*POWER(1+'Inputs'!$D$56,INT(((YEAR(K$5)-YEAR($D$5))*12+MONTH(K$5)-MONTH($D$5))/12)) -> 1855.65 | ... AU41: ='Inputs'!$D$39*POWER(1+'Inputs'!$D$56,INT(((YEAR(AU$5)-YEAR($D$5))*12+MONTH(AU$5)-MONTH($D$5))/12)) -> 2027.7189
...

Sheet Model - Base
A1: 608 Smith Avenue — Base Scenario
A2: Formula-driven 44-month base case. Yellow assumptions live on Inputs; outputs below include cached values for non-calculating readers.
A3: Storefront sales are target-driven illustrations, not observed demand. Founder current cash salary and deferred repayment are separate from economic labor cost.
A5: Metric | B5: Unit | C5: Driver / interpretation | D5: 46296 | E5: 46327 | F5: 46357 | G5: 46388 | H5: 46419 | I5: 46447 | J5: 46478 | K5: 46508 | L5: 46539 | M5: 46569 | N5: 46600 | O5: 46631 | P5: 46661 | Q5: 46692 | R5: 46722 | S5: 46753 | T5: 46784 | U5: 46813 | V5: 46844 | W5: 46874 | X5: 46905 | Y5: 46935 | Z5: 46966 | AA5: 46997 | AB5: 47027 | AC5: 47058 | AD5: 47088 | AE5: 47119 | AF5: 47150 | AG5: 47178 | AH5: 47209 | AI5: 47239 | AJ5: 47270 | AK5: 47300 | AL5: 47331 | AM5: 47362 | AN5: 47392 | AO5: 47423 | AP5: 47453 | AQ5: 47484 | AR5: 47515 | AS5: 47543 | AT5: 47574 | AU5: 47604
A6: REVENUE
A7: Meal Prep Revenue | B7: $/month | C7: Smith food revenue; monthly compound growth | D7: ='Inputs'!$E$18*POWER(1+'Inputs'!$E$19,0) -> 4334.42 | E7: ='Inputs'!$E$18*POWER(1+'Inputs'!$E$19,1) -> 4377.7642 | F7: ='Inputs'!$E$18*POWER(1+'Inputs'!$E$19,2) -> 4421.5418 | G7: ='Inputs'!$E$18*POWER(1+'Inputs'!$E$19,3) -> 4465.7573 | H7: ='Inputs'!$E$18*POWER(1+'Inputs'!$E$19,4) -> 4510.4148 | I7: ='Inputs'!$E$18*POWER(1+'Inputs'!$E$19,5) -> 4555.519 | J7: ='Inputs'!$E$18*POWER(1+'Inputs'!$E$19,6) -> 4601.0742 | K7: ='Inputs'!$E$18*POWER(1+'Inputs'!$E$19,7) -> 4647.0849 | L7: ='Inputs'!$E$18*POWER(1+'Inputs'!$E$19,8) -> 4693.5558 | M7: ='Inputs'!$E$18*POWER(1+'Inputs'!$E$19,9) -> 4740.4913 | N7: ='Inputs'!$E$18*POWER(1+'Inputs'!$E$19,10) -> 4787.8962 | O7: ='Inputs'!$E$18*POWER(1+'Inputs'!$E$19,11) -> 4835.7752 | P7: ='Inputs'!$E$18*POWER(1+'Inputs'!$E$19,12) -> 4884.1329 | Q7: ='Inputs'!$E$18*POWER(1+'Inputs'!$E$19,13) -> 4932.9743 | R7: ='Inputs'!$E$18*POWER(1+'Inputs'!$E$19,14) -> 4982.304 | S7: ='Inputs'!$E$18*POWER(1+'Inputs'!$E$19,15) -> 5032.1271 | T7: ='Inputs'!$E$18*POWER(1+'Inputs'!$E$19,16) -> 5082.4483 | U7: ='Inputs'!$E$18*POWER(1+'Inputs'!$E$19,17) -> 5133.2728 | V7: ='Inputs'!$E$18*POWER(1+'Inputs'!$E$19,18) -> 5184.6055 | W7: ='Inputs'!$E$18*POWER(1+'Inputs'!$E$19,19) -> 5236.4516 | X7: ='Inputs'!$E$18*POWER(1+'Inputs'!$E$19,20) -> 5288.8161 | Y7: ='Inputs'!$E$18*POWER(1+'Inputs'!$E$19,21) -> 5341.7043 | Z7: ='Inputs'!$E$18*POWER(1+'Inputs'!$E$19,22) -> 5395.1213 | AA7: ='Inputs'!$E$18*POWER(1+'Inputs'!$E$19,23) -> 5449.0725 | AB7: ='Inputs'!$E$18*POWER(1+'Inputs'!$E$19,24) -> 5503.5633 | AC7: ='Inputs'!$E$18*POWER(1+'Inputs'!$E$19,25) -> 5558.5989 | AD7: ='Inputs'!$E$18*POWER(1+'Inputs'!$E$19,26) -> 5614.1849 | AE7: ='Inputs'!$E$18*POWER(1+'Inputs'!$E$19,27) -> 5670.3267 | AF7: ='Inputs'!$E$18*POWER(1+'Inputs'!$E$19,28) -> 5727.03 | AG7: ='Inputs'!$E$18*POWER(1+'Inputs'!$E$19,29) -> 5784.3003 | AH7: ='Inputs'!$E$18*POWER(1+'Inputs'!$E$19,30) -> 5842.1433 | AI7: ='Inputs'!$E$18*POWER(1+'Inputs'!$E$19,31) -> 5900.5647 | AJ7: ='Inputs'!$E$18*POWER(1+'Inputs'!$E$19,32) -> 5959.5704 | AK7: ='Inputs'!$E$18*POWER(1+'Inputs'!$E$19,33) -> 6019.1661 | AL7: ='Inputs'!$E$18*POWER(1+'Inputs'!$E$19,34) -> 6079.3577 | AM7: ='Inputs'!$E$18*POWER(1+'Inputs'!$E$19,35) -> 6140.1513 | AN7: ='Inputs'!$E$18*POWER(1+'Inputs'!$E$19,36) -> 6201.5528 | AO7: ='Inputs'!$E$18*POWER(1+'Inputs'!$E$19,37) -> 6263.5684 | AP7: ='Inputs'!$E$18*POWER(1+'Inputs'!$E$19,38) -> 6326.204 | AQ7: ='Inputs'!$E$18*POWER(1+'Inputs'!$E$19,39) -> 6389.4661 | AR7: ='Inputs'!$E$18*POWER(1+'Inputs'!$E$19,40) -> 6453.3607 | AS7: ='Inputs'!$E$18*POWER(1+'Inputs'!$E$19,41) -> 6517.8944 | AT7: ='Inputs'!$E$18*POWER(1+'Inputs'!$E$19,42) -> 6583.0733 | AU7: ='Inputs'!$E$18*POWER(1+'Inputs'!$E$19,43) -> 6648.904
A8: Frozen Pizza Revenue | B8: $/month | C8: Starting units × realized price × unit growth; produced at Hopkins | D8: ='Inputs'!$E$20*POWER(1+'Inputs'!$E$22,0)*'Inputs'!$E$21 -> 1800 | E8: ='Inputs'!$E$20*POWER(1+'Inputs'!$E$22,1)*'Inputs'!$E$21 -> 1827 | F8: ='Inputs'!$E$20*POWER(1+'Inputs'!$E$22,2)*'Inputs'!$E$21 -> 1854.405 | G8: ='Inputs'!$E$20*POWER(1+'Inputs'!$E$22,3)*'Inputs'!$E$21 -> 1882.2211 | H8: ='Inputs'!$E$20*POWER(1+'Inputs'!$E$22,4)*'Inputs'!$E$21 -> 1910.4544 | I8: ='Inputs'!$E$20*POWER(1+'Inputs'!$E$22,5)*'Inputs'!$E$21 -> 1939.1112 | J8: ='Inputs'!$E$20*POWER(1+'Inputs'!$E$22,6)*'Inputs'!$E$21 -> 1968.1979 | K8: ='Inputs'!$E$20*POWER(1+'Inputs'!$E$22,7)*'Inputs'!$E$21 -> 1997.7208 | L8: ='Inputs'!$E$20*POWER(1+'Inputs'!$E$22,8)*'Inputs'!$E$21 -> 2027.6867 | M8: ='Inputs'!$E$20*POWER(1+'Inputs'!$E$22,9)*'Inputs'!$E$21 -> 2058.102 | N8: ='Inputs'!$E$20*POWER(1+'Inputs'!$E$22,10)*'Inputs'!$E$21 -> 2088.9735 | O8: ='Inputs'!$E$20*POWER(1+'Inputs'!$E$22,11)*'Inputs'!$E$21 -> 2120.3081 | P8: ='Inputs'!$E$20*POWER(1+'Inputs'!$E$22,12)*'Inputs'!$E$21 -> 2152.1127 | Q8: ='Inputs'!$E$20*POWER(1+'Inputs'!$E$22,13)*'Inputs'!$E$21 -> 2184.3944 | R8: ='Inputs'!$E$20*POWER(1+'Inputs'!$E$22,14)*'Inputs'!$E$21 -> 2217.1603 | S8: ='Inputs'!$E$20*POWER(1+'Inputs'!$E$22,15)*'Inputs'!$E$21 -> 2250.4177 | T8: ='Inputs'!$E$20*POWER(1+'Inputs'!$E$22,16)*'Inputs'!$E$21 -> 2284.174 | U8: ='Inputs'!$E$20*POWER(1+'Inputs'!$E$22,17)*'Inputs'!$E$21 -> 2318.4366 | V8: ='Inputs'!$E$20*POWER(1+'Inputs'!$E$22,18)*'Inputs'!$E$21 -> 2353.2131 | W8: ='Inputs'!$E$20*POWER(1+'Inputs'!$E$22,19)*'Inputs'!$E$21 -> 2388.5113 | X8: ='Inputs'!$E$20*POWER(1+'Inputs'!$E$22,20)*'Inputs'!$E$21 -> 2424.339 | Y8: ='Inputs'!$E$20*POWER(1+'Inputs'!$E$22,21)*'Inputs'!$E$21 -> 2460.7041 | Z8: ='Inputs'!$E$20*POWER(1+'Inputs'!$E$22,22)*'Inputs'!$E$21 -> 2497.6147 | AA8: ='Inputs'!$E$20*POWER(1+'Inputs'!$E$22,23)*'Inputs'!$E$21 -> 2535.0789 | AB8: ='Inputs'!$E$20*POWER(1+'Inputs'!$E$22,24)*'Inputs'!$E$21 -> 2573.1051 | AC8: ='Inputs'!$E$20*POWER(1+'Inputs'!$E$22,25)*'Inputs'!$E$21 -> 2611.7016 | AD8: ='Inputs'!$E$20*POWER(1+'Inputs'!$E$22,26)*'Inputs'!$E$21 -> 2650.8772 | AE8: ='Inputs'!$E$20*POWER(1+'Inputs'!$E$22,27)*'Inputs'!$E$21 -> 2690.6403 | AF8: ='Inputs'!$E$20*POWER(1+'Inputs'!$E$22,28)*'Inputs'!$E$21 -> 2730.9999 | AG8: ='Inputs'!$E$20*POWER(1+'Inputs'!$E$22,29)*'Inputs'!$E$21 -> 2771.9649 | AH8: ='Inputs'!$E$20*POWER(1+'Inputs'!$E$22,30)*'Inputs'!$E$21 -> 2813.5444 | AI8: ='Inputs'!$E$20*POWER(1+'Inputs'!$E$22,31)*'Inputs'!$E$21 -> 2855.7476 | AJ8: ='Inputs'!$E$20*POWER(1+'Inputs'!$E$22,32)*'Inputs'!$E$21 -> 2898.5838 | AK8: ='Inputs'!$E$20*POWER(1+'Inputs'!$E$22,33)*'Inputs'!$E$21 -> 2942.0625 | AL8: ='Inputs'!$E$20*POWER(1+'Inputs'!$E$22,34)*'Inputs'!$E$21 -> 2986.1935 | AM8: ='Inputs'!$E$20*POWER(1+'Inputs'!$E$22,35)*'Inputs'!$E$21 -> 3030.9864 | AN8: ='Inputs'!$E$20*POWER(1+'Inputs'!$E$22,36)*'Inputs'!$E$21 -> 3076.4512 | AO8: ='Inputs'!$E$20*POWER(1+'Inputs'!$E$22,37)*'Inputs'!$E$21 -> 3122.5979 | AP8: ='Inputs'!$E$20*POWER(1+'Inputs'!$E$22,38)*'Inputs'!$E$21 -> 3169.4369 | AQ8: ='Inputs'!$E$20*POWER(1+'Inputs'!$E$22,39)*'Inputs'!$E$21 -> 3216.9785 | AR8: ='Inputs'!$E$20*POWER(1+'Inputs'!$E$22,40)*'Inputs'!$E$21 -> 3265.2331 | AS8: ='Inputs'!$E$20*POWER(1+'Inputs'!$E$22,41)*'Inputs'!$E$21 -> 3314.2116 | AT8: ='Inputs'!$E$20*POWER(1+'Inputs'!$E$22,42)*'Inputs'!$E$21 -> 3363.9248 | AU8: ='Inputs'!$E$20*POWER(1+'Inputs'!$E$22,43)*'Inputs'!$E$21 -> 3414.3837
A9: Storefront Revenue | B9: $/month | C9: Required Smith sales after meal prep and frozen pizza × six-month ramp | D9: =MAX(0,D36-D7-D8)*(IF(D$5<'Inputs'!$E$23,0,CHOOSE(MIN(7,MAX(1,(YEAR(D$5)-YEAR('Inputs'!$E$23))*12+MONTH(D$5)-MONTH('Inputs'!$E$23)+1)),'Inputs'!$E$50,'Inputs'!$E$51,'Inputs'!$E$52,'Inputs'!$E$53,'Inputs'!$E$54,'Inputs'!$E$55,'Inputs'!$E$55))) -> 0 | E9: =MAX(0,E36-E7-E8)*(IF(E$5<'Inputs'!$E$23,0,CHOOSE(MIN(7,MAX(1,(YEAR(E$5)-YEAR('Inputs'!$E$23))*12+MONTH(E$5)-MONTH('Inputs'!$E$23)+1)),'Inputs'!$E$50,'Inputs'!$E$51,'Inputs'!$E$52,'Inputs'!$E$53,'Inputs'!$E$54,'Inputs'!$E$55,'Inputs'!$E$55))) -> 0 | F9: =MAX(0,F36-F7-F8)*(IF(F$5<'Inputs'!$E$23,0,CHOOSE(MIN(7,MAX(1,(YEAR(F$5)-YEAR('Inputs'!$E$23))*12+MONTH(F$5)-MONTH('Inputs'!$E$23)+1)),'Inputs'!$E$50,'Inputs'!$E$51,'Inputs'!$E$52,'Inputs'!$E$53,'Inputs'!$E$54,'Inputs'!$E$55,'Inputs'!$E$55))) -> 0 | G9: =MAX(0,G36-G7-G8)*(IF(G$5<'Inputs'!$E$23,0,CHOOSE(MIN(7,MAX(1,(YEAR(G$5)-YEAR('Inputs'!$E$23))*12+MONTH(G$5)-MONTH('Inputs'!$E$23)+1)),'Inputs'!$E$50,'Inputs'!$E$51,'Inputs'!$E$52,'Inputs'!$E$53,'Inputs'!$E$54,'Inputs'!$E$55,'Inputs'!$E$55))) -> 0 | H9: =MAX(0,H36-H7-H8)*(IF(H$5<'Inputs'!$E$23,0,CHOOSE(MIN(7,MAX(1,(YEAR(H$5)-YEAR('Inputs'!$E$23))*12+MONTH(H$5)-MONTH('Inputs'!$E$23)+1)),'Inputs'!$E$50,'Inputs'!$E$51,'Inputs'!$E$52,'Inputs'!$E$53,'Inputs'!$E$54,'Inputs'!$E$55,'Inputs'!$E$55))) -> 0 | I9: =MAX(0,I36-I7-I8)*(IF(I$5<'Inputs'!$E$23,0,CHOOSE(MIN(7,MAX(1,(YEAR(I$5)-YEAR('Inputs'!$E$23))*12+MONTH(I$5)-MONTH('Inputs'!$E$23)+1)),'Inputs'!$E$50,'Inputs'!$E$51,'Inputs'!$E$52,'Inputs'!$E$53,'Inputs'!$E$54,'Inputs'!$E$55,'Inputs'!$E$55))) -> 10990.037 | J9: =MAX(0,J36-J7-J8)*(IF(J$5<'Inputs'!$E$23,0,CHOOSE(MIN(7,MAX(1,(YEAR(J$5)-YEAR('Inputs'!$E$23))*12+MONTH(J$5)-MONTH('Inputs'!$E$23)+1)),'Inputs'!$E$50,'Inputs'!$E$51,'Inputs'!$E$52,'Inputs'!$E$53,'Inputs'!$E$54,'Inputs'!$E$55,'Inputs'!$E$55))) -> 15662.732 | K9: =MAX(0,K36-K7-K8)*(IF(K$5<'Inputs'!$E$23,0,CHOOSE(MIN(7,MAX(1,(YEAR(K$5)-YEAR('Inputs'!$E$23))*12+MONTH(K$5)-MONTH('Inputs'!$E$23)+1)),'Inputs'!$E$50,'Inputs'!$E$51,'Inputs'!$E$52,'Inputs'!$E$53,'Inputs'!$E$54,'Inputs'!$E$55,'Inputs'!$E$55))) -> 20312.455 | ... AU9: =MAX(0,AU36-AU7-AU8)*(IF(AU$5<'Inputs'!$E$23,0,CHOOSE(MIN(7,MAX(1,(YEAR(AU$5)-YEAR('Inputs'!$E$23))*12+MONTH(AU$5)-MONTH('Inputs'!$E$23)+1)),'Inputs'!$E$50,'Inputs'!$E$51,'Inputs'!$E$52,'Inputs'!$E$53,'Inputs'!$E$54,'Inputs'!$E$55,'Inputs'!$E$55))) -> 42178.818
A10: Smith Revenue | B10: $/month | C10: Meal prep + frozen pizza + storefront | D10: =SUM(D7:D9) -> 6134.42 | E10: =SUM(E7:E9) -> 6204.7642 | F10: =SUM(F7:F9) -> 6275.9468 | G10: =SUM(G7:G9) -> 6347.9783 | H10: =SUM(H7:H9) -> 6420.8692 | I10: =SUM(I7:I9) -> 17484.668 | J10: =SUM(J7:J9) -> 22232.004 | K10: =SUM(K7:K9) -> 26957.261 | ... AU10: =SUM(AU7:AU9) -> 52242.105
A11: Airbnb Revenue | B11: $/month | C11: Nonfood revenue at the second venue | D11: ='Inputs'!$E$11*'Inputs'!$E$48*(IF(D$5<'Inputs'!$E$57,0,IF(D$5<='Inputs'!$E$58,'Inputs'!$E$10,IF(D$5>='Inputs'!$E$59,'Inputs'!$E$9,0)))) -> 5400 | E11: ='Inputs'!$E$11*'Inputs'!$E$48*(IF(E$5<'Inputs'!$E$57,0,IF(E$5<='Inputs'!$E$58,'Inputs'!$E$10,IF(E$5>='Inputs'!$E$59,'Inputs'!$E$9,0)))) -> 5400 | F11: ='Inputs'!$E$11*'Inputs'!$E$48*(IF(F$5<'Inputs'!$E$57,0,IF(F$5<='Inputs'!$E$58,'Inputs'!$E$10,IF(F$5>='Inputs'!$E$59,'Inputs'!$E$9,0)))) -> 5400 | G11: ='Inputs'!$E$11*'Inputs'!$E$48*(IF(G$5<'Inputs'!$E$57,0,IF(G$5<='Inputs'!$E$58,'Inputs'!$E$10,IF(G$5>='Inputs'!$E$59,'Inputs'!$E$9,0)))) -> 7200 | H11: ='Inputs'!$E$11*'Inputs'!$E$48*(IF(H$5<'Inputs'!$E$57,0,IF(H$5<='Inputs'!$E$58,'Inputs'!$E$10,IF(H$5>='Inputs'!$E$59,'Inputs'!$E$9,0)))) -> 7200 | I11: ='Inputs'!$E$11*'Inputs'!$E$48*(IF(I$5<'Inputs'!$E$57,0,IF(I$5<='Inputs'!$E$58,'Inputs'!$E$10,IF(I$5>='Inputs'!$E$59,'Inputs'!$E$9,0)))) -> 7200 | J11: ='Inputs'!$E$11*'Inputs'!$E$48*(IF(J$5<'Inputs'!$E$57,0,IF(J$5<='Inputs'!$E$58,'Inputs'!$E$10,IF(J$5>='Inputs'!$E$59,'Inputs'!$E$9,0)))) -> 7200 | K11: ='Inputs'!$E$11*'Inputs'!$E$48*(IF(K$5<'Inputs'!$E$57,0,IF(K$5<='Inputs'!$E$58,'Inputs'!$E$10,IF(K$5>='Inputs'!$E$59,'Inputs'!$E$9,0)))) -> 7200 | ... AU11: ='Inputs'!$E$11*'Inputs'!$E$48*(IF(AU$5<'Inputs'!$E$57,0,IF(AU$5<='Inputs'!$E$58,'Inputs'!$E$10,IF(AU$5>='Inputs'!$E$59,'Inputs'!$E$9,0)))) -> 7200
A12: Small Events Revenue | B12: $/month | C12: Gross small-event revenue | D12: ='Inputs'!$E$13*'Inputs'!$E$14*(IF(D$5<'Inputs'!$E$57,0,IF(D$5<='Inputs'!$E$58,'Inputs'!$E$10,IF(D$5>='Inputs'!$E$59,'Inputs'!$E$9,0)))) -> 3150 | E12: ='Inputs'!$E$13*'Inputs'!$E$14*(IF(E$5<'Inputs'!$E$57,0,IF(E$5<='Inputs'!$E$58,'Inputs'!$E$10,IF(E$5>='Inputs'!$E$59,'Inputs'!$E$9,0)))) -> 3150 | F12: ='Inputs'!$E$13*'Inputs'!$E$14*(IF(F$5<'Inputs'!$E$57,0,IF(F$5<='Inputs'!$E$58,'Inputs'!$E$10,IF(F$5>='Inputs'!$E$59,'Inputs'!$E$9,0)))) -> 3150 | G12: ='Inputs'!$E$13*'Inputs'!$E$14*(IF(G$5<'Inputs'!$E$57,0,IF(G$5<='Inputs'!$E$58,'Inputs'!$E$10,IF(G$5>='Inputs'!$E$59,'Inputs'!$E$9,0)))) -> 4200 | H12: ='Inputs'!$E$13*'Inputs'!$E$14*(IF(H$5<'Inputs'!$E$57,0,IF(H$5<='Inputs'!$E$58,'Inputs'!$E$10,IF(H$5>='Inputs'!$E$59,'Inputs'!$E$9,0)))) -> 4200 | I12: ='Inputs'!$E$13*'Inputs'!$E$14*(IF(I$5<'Inputs'!$E$57,0,IF(I$5<='Inputs'!$E$58,'Inputs'!$E$10,IF(I$5>='Inputs'!$E$59,'Inputs'!$E$9,0)))) -> 4200 | J12: ='Inputs'!$E$13*'Inputs'!$E$14*(IF(J$5<'Inputs'!$E$57,0,IF(J$5<='Inputs'!$E$58,'Inputs'!$E$10,IF(J$5>='Inputs'!$E$59,'Inputs'!$E$9,0)))) -> 4200 | K12: ='Inputs'!$E$13*'Inputs'!$E$14*(IF(K$5<'Inputs'!$E$57,0,IF(K$5<='Inputs'!$E$58,'Inputs'!$E$10,IF(K$5>='Inputs'!$E$59,'Inputs'!$E$9,0)))) -> 4200 | ... AU12: ='Inputs'!$E$13*'Inputs'!$E$14*(IF(AU$5<'Inputs'!$E$57,0,IF(AU$5<='Inputs'!$E$58,'Inputs'!$E$10,IF(AU$5>='Inputs'!$E$59,'Inputs'!$E$9,0)))) -> 4200
A13: Personal Chef Revenue | B13: $/month | C13: Food revenue from packages at the second venue | D13: ='Inputs'!$E$16*'Inputs'!$E$17*(IF(D$5<'Inputs'!$E$57,0,IF(D$5<='Inputs'!$E$58,'Inputs'!$E$10,IF(D$5>='Inputs'!$E$59,'Inputs'!$E$9,0)))) -> 1800 | E13: ='Inputs'!$E$16*'Inputs'!$E$17*(IF(E$5<'Inputs'!$E$57,0,IF(E$5<='Inputs'!$E$58,'Inputs'!$E$10,IF(E$5>='Inputs'!$E$59,'Inputs'!$E$9,0)))) -> 1800 | F13: ='Inputs'!$E$16*'Inputs'!$E$17*(IF(F$5<'Inputs'!$E$57,0,IF(F$5<='Inputs'!$E$58,'Inputs'!$E$10,IF(F$5>='Inputs'!$E$59,'Inputs'!$E$9,0)))) -> 1800 | G13: ='Inputs'!$E$16*'Inputs'!$E$17*(IF(G$5<'Inputs'!$E$57,0,IF(G$5<='Inputs'!$E$58,'Inputs'!$E$10,IF(G$5>='Inputs'!$E$59,'Inputs'!$E$9,0)))) -> 2400 | H13: ='Inputs'!$E$16*'Inputs'!$E$17*(IF(H$5<'Inputs'!$E$57,0,IF(H$5<='Inputs'!$E$58,'Inputs'!$E$10,IF(H$5>='Inputs'!$E$59,'Inputs'!$E$9,0)))) -> 2400 | I13: ='Inputs'!$E$16*'Inputs'!$E$17*(IF(I$5<'Inputs'!$E$57,0,IF(I$5<='Inputs'!$E$58,'Inputs'!$E$10,IF(I$5>='Inputs'!$E$59,'Inputs'!$E$9,0)))) -> 2400 | J13: ='Inputs'!$E$16*'Inputs'!$E$17*(IF(J$5<'Inputs'!$E$57,0,IF(J$5<='Inputs'!$E$58,'Inputs'!$E$10,IF(J$5>='Inputs'!$E$59,'Inputs'!$E$9,0)))) -> 2400 | K13: ='Inputs'!$E$16*'Inputs'!$E$17*(IF(K$5<'Inputs'!$E$57,0,IF(K$5<='Inputs'!$E$58,'Inputs'!$E$10,IF(K$5>='Inputs'!$E$59,'Inputs'!$E$9,0)))) -> 2400 | ... AU13: ='Inputs'!$E$16*'Inputs'!$E$17*(IF(AU$5<'Inputs'!$E$57,0,IF(AU$5<='Inputs'!$E$58,'Inputs'!$E$10,IF(AU$5>='Inputs'!$E$59,'Inputs'!$E$9,0)))) -> 2400
A14: Second Venue Revenue | B14: $/month | C14: Airbnb + small events + personal chef | D14: =SUM(D11:D13) -> 10350 | E14: =SUM(E11:E13) -> 10350 | F14: =SUM(F11:F13) -> 10350 | G14: =SUM(G11:G13) -> 13800 | H14: =SUM(H11:H13) -> 13800 | I14: =SUM(I11:I13) -> 13800 | J14: =SUM(J11:J13) -> 13800 | K14: =SUM(K11:K13) -> 13800 | ... AU14: =SUM(AU11:AU13) -> 13800
A15: Total Revenue | B15: $/month | C15: Smith + second venue | D15: =D10+D14 -> 16484.42 | E15: =E10+E14 -> 16554.764 | F15: =F10+F14 -> 16625.947 | G15: =G10+G14 -> 20147.978 | H15: =H10+H14 -> 20220.869 | I15: =I10+I14 -> 31284.668 | J15: =J10+J14 -> 36032.004 | K15: =K10+K14 -> 40757.261 | ... AU15: =AU10+AU14 -> 66042.105
A16: Food Revenue | B16: $/month | C16: Smith + event food component + personal chef | D16: =D10+'Inputs'!$E$13*'Inputs'!$E$15*(IF(D$5<'Inputs'!$E$57,0,IF(D$5<='Inputs'!$E$58,'Inputs'!$E$10,IF(D$5>='Inputs'!$E$59,'Inputs'!$E$9,0))))+D13 -> 9959.42 | E16: =E10+'Inputs'!$E$13*'Inputs'!$E$15*(IF(E$5<'Inputs'!$E$57,0,IF(E$5<='Inputs'!$E$58,'Inputs'!$E$10,IF(E$5>='Inputs'!$E$59,'Inputs'!$E$9,0))))+E13 -> 10029.764 | F16: =F10+'Inputs'!$E$13*'Inputs'!$E$15*(IF(F$5<'Inputs'!$E$57,0,IF(F$5<='Inputs'!$E$58,'Inputs'!$E$10,IF(F$5>='Inputs'!$E$59,'Inputs'!$E$9,0))))+F13 -> 10100.947 | G16: =G10+'Inputs'!$E$13*'Inputs'!$E$15*(IF(G$5<'Inputs'!$E$57,0,IF(G$5<='Inputs'!$E$58,'Inputs'!$E$10,IF(G$5>='Inputs'!$E$59,'Inputs'!$E$9,0))))+G13 -> 11447.978 | H16: =H10+'Inputs'!$E$13*'Inputs'!$E$15*(IF(H$5<'Inputs'!$E$57,0,IF(H$5<='Inputs'!$E$58,'Inputs'!$E$10,IF(H$5>='Inputs'!$E$59,'Inputs'!$E$9,0))))+H13 -> 11520.869 | I16: =I10+'Inputs'!$E$13*'Inputs'!$E$15*(IF(I$5<'Inputs'!$E$57,0,IF(I$5<='Inputs'!$E$58,'Inputs'!$E$10,IF(I$5>='Inputs'!$E$59,'Inputs'!$E$9,0))))+I13 -> 22584.668 | J16: =J10+'Inputs'!$E$13*'Inputs'!$E$15*(IF(J$5<'Inputs'!$E$57,0,IF(J$5<='Inputs'!$E$58,'Inputs'!$E$10,IF(J$5>='Inputs'!$E$59,'Inputs'!$E$9,0))))+J13 -> 27332.004 | K16: =K10+'Inputs'!$E$13*'Inputs'!$E$15*(IF(K$5<'Inputs'!$E$57,0,IF(K$5<='Inputs'!$E$58,'Inputs'!$E$10,IF(K$5>='Inputs'!$E$59,'Inputs'!$E$9,0))))+K13 -> 32057.261 | ... AU16: =AU10+'Inputs'!$E$13*'Inputs'!$E$15*(IF(AU$5<'Inputs'!$E$57,0,IF(AU$5<='Inputs'!$E$58,'Inputs'!$E$10,IF(AU$5>='Inputs'!$E$59,'Inputs'!$E$9,0))))+AU13 -> 57342.105
A17: COST OF SALES & LABOR
A18: Food COGS | B18: $/month | C18: Applied only to food revenue | D18: =D16*'Inputs'!$E$27 -> 2091.4782 | E18: =E16*'Inputs'!$E$27 -> 2106.2505 | F18: =F16*'Inputs'!$E$27 -> 2121.1988 | G18: =G16*'Inputs'!$E$27 -> 2404.0755 | H18: =H16*'Inputs'!$E$27 -> 2419.3825 | I18: =I16*'Inputs'!$E$27 -> 4742.7802 | J18: =J16*'Inputs'!$E$27 -> 5739.7209 | K18: =K16*'Inputs'!$E$27 -> 6732.0248 | ... AU18: =AU16*'Inputs'!$E$27 -> 12041.842
A19: Food Cost % | B19: % revenue | C19: Food COGS ÷ food revenue | D19: =IFERROR(D18/D16,0) -> 0.21 | E19: =IFERROR(E18/E16,0) -> 0.21 | F19: =IFERROR(F18/F16,0) -> 0.21 | G19: =IFERROR(G18/G16,0) -> 0.21 | H19: =IFERROR(H18/H16,0) -> 0.21 | I19: =IFERROR(I18/I16,0) -> 0.21 | J19: =IFERROR(J18/J16,0) -> 0.21 | K19: =IFERROR(K18/K16,0) -> 0.21 | ... AU19: =IFERROR(AU18/AU16,0) -> 0.21
A20: Venue Variable Cost | B20: $/month | C20: Applied only to Airbnb revenue | D20: =D11*'Inputs'!$E$12 -> 972 | E20: =E11*'Inputs'!$E$12 -> 972 | F20: =F11*'Inputs'!$E$12 -> 972 | G20: =G11*'Inputs'!$E$12 -> 1296 | H20: =H11*'Inputs'!$E$12 -> 1296 | I20: =I11*'Inputs'!$E$12 -> 1296 | J20: =J11*'Inputs'!$E$12 -> 1296 | K20: =K11*'Inputs'!$E$12 -> 1296 | ... AU20: =AU11*'Inputs'!$E$12 -> 1296
A21: Packaging & Delivery | B21: $/month | C21: Applied to food revenue | D21: =D16*'Inputs'!$E$37 -> 298.7826 | E21: =E16*'Inputs'!$E$37 -> 300.89293 | F21: =F16*'Inputs'!$E$37 -> 303.02841 | G21: =G16*'Inputs'!$E$37 -> 343.43935 | H21: =H16*'Inputs'!$E$37 -> 345.62608 | I21: =I16*'Inputs'!$E$37 -> 677.54003 | J21: =J16*'Inputs'!$E$37 -> 819.96013 | K21: =K16*'Inputs'!$E$37 -> 961.71783 | ... AU21: =AU16*'Inputs'!$E$37 -> 1720.2632
A22: Direct Paid Labor | B22: $/month | C22: Phase rate × total revenue | D22: =D15*(IF(D$5<'Inputs'!$E$23,'Inputs'!$E$28,IF(D$5<EDATE('Inputs'!$E$23,6),'Inputs'!$E$29,'Inputs'!$E$30))) -> 1978.1304 | E22: =E15*(IF(E$5<'Inputs'!$E$23,'Inputs'!$E$28,IF(E$5<EDATE('Inputs'!$E$23,6),'Inputs'!$E$29,'Inputs'!$E$30))) -> 1986.5717 | F22: =F15*(IF(F$5<'Inputs'!$E$23,'Inputs'!$E$28,IF(F$5<EDATE('Inputs'!$E$23,6),'Inputs'!$E$29,'Inputs'!$E$30))) -> 1995.1136 | G22: =G15*(IF(G$5<'Inputs'!$E$23,'Inputs'!$E$28,IF(G$5<EDATE('Inputs'!$E$23,6),'Inputs'!$E$29,'Inputs'!$E$30))) -> 2417.7574 | H22: =H15*(IF(H$5<'Inputs'!$E$23,'Inputs'!$E$28,IF(H$5<EDATE('Inputs'!$E$23,6),'Inputs'!$E$29,'Inputs'!$E$30))) -> 2426.5043 | I22: =I15*(IF(I$5<'Inputs'!$E$23,'Inputs'!$E$28,IF(I$5<EDATE('Inputs'!$E$23,6),'Inputs'!$E$29,'Inputs'!$E$30))) -> 5318.3935 | J22: =J15*(IF(J$5<'Inputs'!$E$23,'Inputs'!$E$28,IF(J$5<EDATE('Inputs'!$E$23,6),'Inputs'!$E$29,'Inputs'!$E$30))) -> 6125.4408 | K22: =K15*(IF(K$5<'Inputs'!$E$23,'Inputs'!$E$28,IF(K$5<EDATE('Inputs'!$E$23,6),'Inputs'!$E$29,'Inputs'!$E$30))) -> 6928.7344 | ... AU22: =AU15*(IF(AU$5<'Inputs'!$E$23,'Inputs'!$E$28,IF(AU$5<EDATE('Inputs'!$E$23,6),'Inputs'!$E$29,'Inputs'!$E$30))) -> 9245.8947
A23: Founder Economic Salary | B23: $/month | C23: Catherine + Weston combined economic compensation | D23: ='Inputs'!$E$32 -> 7500 | E23: ='Inputs'!$E$32 -> 7500 | F23: ='Inputs'!$E$32 -> 7500 | G23: ='Inputs'!$E$32 -> 7500 | H23: ='Inputs'!$E$32 -> 7500 | I23: ='Inputs'!$E$32 -> 7500 | J23: ='Inputs'!$E$32 -> 7500 | K23: ='Inputs'!$E$32 -> 7500 | ... AU23: ='Inputs'!$E$32 -> 7500
A24: Direct Payroll Burden | B24: $/month | C24: Burden on direct paid labor | D24: =D22*'Inputs'!$E$31 -> 197.81304 | E24: =E22*'Inputs'!$E$31 -> 198.65717 | F24: =F22*'Inputs'!$E$31 -> 199.51136 | G24: =G22*'Inputs'!$E$31 -> 241.77574 | H24: =H22*'Inputs'!$E$31 -> 242.65043 | I24: =I22*'Inputs'!$E$31 -> 531.83935 | J24: =J22*'Inputs'!$E$31 -> 612.54408 | K24: =K22*'Inputs'!$E$31 -> 692.87344 | ... AU24: =AU22*'Inputs'!$E$31 -> 924.58947
A25: Total Labor | B25: $/month | C25: Direct labor + founder economic compensation + burden | D25: =SUM(D22,D23,D24) -> 9675.9434 | E25: =SUM(E22,E23,E24) -> 9685.2289 | F25: =SUM(F22,F23,F24) -> 9694.625 | G25: =SUM(G22,G23,G24) -> 10159.533 | H25: =SUM(H22,H23,H24) -> 10169.155 | I25: =SUM(I22,I23,I24) -> 13350.233 | J25: =SUM(J22,J23,J24) -> 14237.985 | K25: =SUM(K22,K23,K24) -> 15121.608 | ... AU25: =SUM(AU22,AU23,AU24) -> 17670.484
A26: Total Labor % | B26: % revenue | C26: Total labor ÷ total revenue | D26: =IFERROR(D25/D15,0) -> 0.58697506 | E26: =IFERROR(E25/E15,0) -> 0.58504179 | F26: =IFERROR(F25/F15,0) -> 0.58310213 | G26: =IFERROR(G25/G15,0) -> 0.50424578 | H26: =IFERROR(H25/H15,0) -> 0.50290394 | I26: =IFERROR(I25/I15,0) -> 0.42673405 | J26: =IFERROR(J25/J15,0) -> 0.39514829 | K26: =IFERROR(K25/K15,0) -> 0.37101629 | ... AU26: =IFERROR(AU25/AU15,0) -> 0.26756391
A27: OCCUPANCY & REQUIRED SALES
A28: Smith Rent & NNN | B28: $/month | C28: Owner-provided stepped rent schedule | D28: =IF(D$5<DATE(2026,10,1),'Inputs'!$E$41,IF(D$5<DATE(2027,1,1),'Inputs'!$E$42,IF(D$5<DATE(2027,6,1),'Inputs'!$E$43,IF(D$5<DATE(2028,1,1),'Inputs'!$E$44,'Inputs'!$E$45)))) -> 1800 | E28: =IF(E$5<DATE(2026,10,1),'Inputs'!$E$41,IF(E$5<DATE(2027,1,1),'Inputs'!$E$42,IF(E$5<DATE(2027,6,1),'Inputs'!$E$43,IF(E$5<DATE(2028,1,1),'Inputs'!$E$44,'Inputs'!$E$45)))) -> 1800 | F28: =IF(F$5<DATE(2026,10,1),'Inputs'!$E$41,IF(F$5<DATE(2027,1,1),'Inputs'!$E$42,IF(F$5<DATE(2027,6,1),'Inputs'!$E$43,IF(F$5<DATE(2028,1,1),'Inputs'!$E$44,'Inputs'!$E$45)))) -> 1800 | G28: =IF(G$5<DATE(2026,10,1),'Inputs'!$E$41,IF(G$5<DATE(2027,1,1),'Inputs'!$E$42,IF(G$5<DATE(2027,6,1),'Inputs'!$E$43,IF(G$5<DATE(2028,1,1),'Inputs'!$E$44,'Inputs'!$E$45)))) -> 2600 | H28: =IF(H$5<DATE(2026,10,1),'Inputs'!$E$41,IF(H$5<DATE(2027,1,1),'Inputs'!$E$42,IF(H$5<DATE(2027,6,1),'Inputs'!$E$43,IF(H$5<DATE(2028,1,1),'Inputs'!$E$44,'Inputs'!$E$45)))) -> 2600 | I28: =IF(I$5<DATE(2026,10,1),'Inputs'!$E$41,IF(I$5<DATE(2027,1,1),'Inputs'!$E$42,IF(I$5<DATE(2027,6,1),'Inputs'!$E$43,IF(I$5<DATE(2028,1,1),'Inputs'!$E$44,'Inputs'!$E$45)))) -> 2600 | J28: =IF(J$5<DATE(2026,10,1),'Inputs'!$E$41,IF(J$5<DATE(2027,1,1),'Inputs'!$E$42,IF(J$5<DATE(2027,6,1),'Inputs'!$E$43,IF(J$5<DATE(2028,1,1),'Inputs'!$E$44,'Inputs'!$E$45)))) -> 2600 | K28: =IF(K$5<DATE(2026,10,1),'Inputs'!$E$41,IF(K$5<DATE(2027,1,1),'Inputs'!$E$42,IF(K$5<DATE(2027,6,1),'Inputs'!$E$43,IF(K$5<DATE(2028,1,1),'Inputs'!$E$44,'Inputs'!$E$45)))) -> 2600 | ... AU28: =IF(AU$5<DATE(2026,10,1),'Inputs'!$E$41,IF(AU$5<DATE(2027,1,1),'Inputs'!$E$42,IF(AU$5<DATE(2027,6,1),'Inputs'!$E$43,IF(AU$5<DATE(2028,1,1),'Inputs'!$E$44,'Inputs'!$E$45)))) -> 3963
